Workbook

Sheet Inputs
B2: Employee Profile
B3: Current Age | C3: 35
B4: Retirement Age | C4: 65
B5: Life Expectancy (max age) | C5: 85
B6: Current Annual Salary | C6: 60000
B8: Actuarial Assumptions
B9: Annual Salary Growth Rate | C9: 0.03
B10: Discount Rate | C10: 0.05
B11: Pension Accrual Rate | C11: 0.015
B12: Notes
B15: Years to Retirement | C15: =C4-C3 -> 30
B16: Years of Pension Payments | C16: =C5-C4 -> 20
B17: Final Salary (projected) | C17: =C6*(1+C9)^C15 -> 145635.75
B18: Annual Pension Benefit | C18: =C11*C17*C15 -> 65536.087

Sheet Calculations
D8: Assuming pension increases with slary growth (cola) cost of living adjustment
B9: Assumption : increases 10% per yr | F9: (present value factor)
A10: Age | B10: Mortality Rate | C10: Survival Probability | D10: Pension Payment | E10: Years from Now | F10: PV Factor | G10: Expected Payment | H10: PV of Expected Payment
A11: =Inputs!$C$4 -> 65 | B11: 0.01 | C11: 1 | D11: =Inputs!$C$18 -> 65536.087 | E11: =A11- Inputs!$C$3 -> 30 | F11: =1/(1+ Inputs!$C$10)^E11 -> 0.23137745 | G11: =D11*C11 -> 65536.087 | H11: =G11*F11 -> 15163.573
A12: =A11+1 -> 66 | B12: =B11*1.1 -> 0.011 | C12: =C11*(1-B11) -> 0.99 | D12: =D11*(1+Inputs!$C$9) -> 67502.169 | E12: =A12- Inputs!$C$3 -> 31 | F12: =1/(1+ Inputs!$C$10)^E12 -> 0.22035947 | G12: =D12*C12 -> 66827.148 | H12: =G12*F12 -> 14725.995
A13: =A12+1 -> 67 | B13: =B12*1.1 -> 0.0121 | C13: =C12*(1-B12) -> 0.97911 | D13: =D12*(1+Inputs!$C$9) -> 69527.234 | E13: =A13- Inputs!$C$3 -> 32 | F13: =1/(1+ Inputs!$C$10)^E13 -> 0.20986617 | G13: =D13*C13 -> 68074.81 | H13: =G13*F13 -> 14286.6
A14: =A13+1 -> 68 | B14: =B13*1.1 -> 0.01331 | C14: =C13*(1-B13) -> 0.96726277 | D14: =D13*(1+Inputs!$C$9) -> 71613.051 | E14: =A14- Inputs!$C$3 -> 33 | F14: =1/(1+ Inputs!$C$10)^E14 -> 0.19987254 | G14: =D14*C14 -> 69268.638 | H14: =G14*F14 -> 13844.899
A15: =A14+1 -> 69 | B15: =B14*1.1 -> 0.014641 | C15: =C14*(1-B14) -> 0.9543885 | D15: =D14*(1+Inputs!$C$9) -> 73761.443 | E15: =A15- Inputs!$C$3 -> 34 | F15: =1/(1+ Inputs!$C$10)^E15 -> 0.1903548 | G15: =D15*C15 -> 70397.073 | H15: =G15*F15 -> 13400.421
A16: =A15+1 -> 70 | B16: =B15*1.1 -> 0.0161051 | C16: =C15*(1-B15) -> 0.9404153 | D16: =D15*(1+Inputs!$C$9) -> 75974.286 | E16: =A16- Inputs!$C$3 -> 35 | F16: =1/(1+ Inputs!$C$10)^E16 -> 0.18129029 | G16: =D16*C16 -> 71447.381 | H16: =G16*F16 -> 12952.716
A17: =A16+1 -> 71 | B17: =B16*1.1 -> 0.01771561 | C17: =C16*(1-B16) -> 0.92526982 | D17: =D16*(1+Inputs!$C$9) -> 78253.515 | E17: =A17- Inputs!$C$3 -> 36 | F17: =1/(1+ Inputs!$C$10)^E17 -> 0.17265741 | G17: =D17*C17 -> 72405.615 | H17: =G17*F17 -> 12501.366
A18: =A17+1 -> 72 | B18: =B17*1.1 -> 0.019487171 | C18: =C17*(1-B17) -> 0.9088781 | D18: =D17*(1+Inputs!$C$9) -> 80601.12 | E18: =A18- Inputs!$C$3 -> 37 | F18: =1/(1+ Inputs!$C$10)^E18 -> 0.16443563 | G18: =D18*C18 -> 73256.593 | H18: =G18*F18 -> 12045.994
A19: =A18+1 -> 73 | B19: =B18*1.1 -> 0.021435888 | C19: =C18*(1-B18) -> 0.89116663 | D19: =D18*(1+Inputs!$C$9) -> 83019.154 | E19: =A19- Inputs!$C$3 -> 38 | F19: =1/(1+ Inputs!$C$10)^E19 -> 0.15660536 | G19: =D19*C19 -> 73983.9 | H19: =G19*F19 -> 11586.276
A20: =A19+1 -> 74 | B20: =B19*1.1 -> 0.023579477 | C20: =C19*(1-B19) -> 0.87206369 | D20: =D19*(1+Inputs!$C$9) -> 85509.729 | E20: =A20- Inputs!$C$3 -> 39 | F20: =1/(1+ Inputs!$C$10)^E20 -> 0.14914797 | G20: =D20*C20 -> 74569.929 | H20: =G20*F20 -> 11121.953
A21: =A20+1 -> 75 | B21: =B20*1.1 -> 0.025937425 | C21: =C20*(1-B20) -> 0.85150088 | D21: =D20*(1+Inputs!$C$9) -> 88075.02 | E21: =A21- Inputs!$C$3 -> 40 | F21: =1/(1+ Inputs!$C$10)^E21 -> 0.14204568 | G21: =D21*C21 -> 74995.957 | H21: =G21*F21 -> 10652.852
A22: =A21+1 -> 76 | B22: =B21*1.1 -> 0.028531167 | C22: =C21*(1-B21) -> 0.82941514 | D22: =D21*(1+Inputs!$C$9) -> 90717.271 | E22: =A22- Inputs!$C$3 -> 41 | F22: =1/(1+ Inputs!$C$10)^E22 -> 0.1352816 | G22: =D22*C22 -> 75242.278 | H22: =G22*F22 -> 10178.896
A23: =A22+1 -> 77 | B23: =B22*1.1 -> 0.031384284 | C23: =C22*(1-B22) -> 0.80575096 | D23: =D22*(1+Inputs!$C$9) -> 93438.789 | E23: =A23- Inputs!$C$3 -> 42 | F23: =1/(1+ Inputs!$C$10)^E23 -> 0.12883962 | G23: =D23*C23 -> 75288.394 | H23: =G23*F23 -> 9700.1282
... A31: =A30+1 -> 85 | B31: =B30*1.1 -> 0.067274999 | C31: =C30*(1-B30) -> 0.55788355 | D31: =D30*(1+Inputs!$C$9) -> 118365.46 | E31: =A31- Inputs!$C$3 -> 50 | F31: =1/(1+ Inputs!$C$10)^E31 -> 0.087203727 | G31: =D31*C31 -> 66034.144 | H31: =G31*F31 -> 5758.4235
H32: =SUM(H11:H31) -> 222095.23

Sheet Sensitivity
A1: Discount Rate Sensitivity Analysis
A3: Discount Rate | B3: Total Liability | C3: Change from Base | D3: % Change
A4: 0.03 | B4: 467444.42 | C4: =B4-$B$6 -> 245349.19 | D4: =C4/$B$6 *100 -> 110.47027
A5: 0.04 | B5: 321120.67 | C5: =B5-$B$6 -> 99025.445 | D5: =C5/$B$6 *100 -> 44.58693
A6: 5% (base rate) | B6: 222095.23 | C6: =B6-$B$6 -> 0 | D6: =C6/$B$6 *100 -> 0
A7: 0.06 | B7: 154615.52 | C7: =B7-$B$6 -> -67479.71 | D7: =C7/$B$6 *100 -> -30.383233
A8: 0.07 | B8: 108322.66 | C8: =B8-$B$6 -> -113772.57 | D8: =C8/$B$6 *100 -> -51.226929
A14: Salary Growth Sensitivity Analysis
A16: Salary Growth | B16: Final Salary | C16: Annual Pension | D16: Total Liability | E16: Change from Base | F16: % Change
A17: 0.01 | B17: 80870.935 | C17: =B17 * Inputs!$C$11 * Inputs!$C$15 -> 36391.921 | D17: 105340.16 | E17: =D17-$D$19 -> -116755.07 | F17: =E17/$D$19 *100 -> -52.569821
A18: 0.02 | B18: 108681.7 | C18: =B18 * Inputs!$C$11 * Inputs!$C$15 -> 48906.763 | D18: 152992.14 | E18: =D18-$D$19 -> -69103.085 | F18: =E18/$D$19 *100 -> -31.114169
A19: 3% (base growth) | B19: 145635.75 | C19: =B19 * Inputs!$C$11 * Inputs!$C$15 -> 65536.087 | D19: 222095.23 | E19: =D19-$D$19 -> 0 | F19: =E19/$D$19 *100 -> 0
A20: 0.04 | B20: 194603.85 | C20: =B20 * Inputs!$C$11 * Inputs!$C$15 -> 87571.733 | D20: 322271.62 | E20: =D20-$D$19 -> 100176.39 | F20: =E20/$D$19 *100 -> 45.105152
A21: 0.05 | B21: 259316.54 | C21: =B21 * Inputs!$C$11 * Inputs!$C$15 -> 116692.44 | D21: 467444.42 | E21: =D21-$D$19 -> 245349.19 | F21: =E21/$D$19 *100 -> 110.47027
A27: Retirement Age Sensitivity Analysis
A29: Retirement Age | B29: Years of Service | C29: Final Salary | D29: Annual Pension | E29: Total Liability | F29: Change from Base | G29: % Change
A30: 63 | B30: =A30-Inputs!$C$3 -> 28 | C30: 137275.66 | D30: =C30* Inputs!$C$11 * Inputs!$C$15 -> 61774.047 | E30: 215417.09 | F30: =E30-$E$32 -> -6678.1391 | G30: =F30/$E$32 *100 -> -3.006881
A31: 64 | B31: =A31-Inputs!$C$3 -> 29 | C31: 141393.93 | D31: =C31* Inputs!$C$11 * Inputs!$C$15 -> 63627.269 | E31: 218860.83 | F31: =E31-$E$32 -> -3234.3965 | G31: =F31/$E$32 *100 -> -1.4563107
A32: 65 | B32: =A32-Inputs!$C$3 -> 30 | C32: 145635.75 | D32: =C32* Inputs!$C$11 * Inputs!$C$15 -> 65536.087 | E32: 222095.23 | F32: =E32-$E$32 -> 0 | G32: =F32/$E$32 *100 -> 0
A33: 66 | B33: =A33-Inputs!$C$3 -> 31 | C33: 150004.82 | D33: =C33* Inputs!$C$11 * Inputs!$C$15 -> 67502.169 | E33: 225127.01 | F33: =E33-$E$32 -> 3031.7761 | G33: =F33/$E$32 *100 -> 1.3650794
A34: 67 | B34: =A34-Inputs!$C$3 -> 32 | C34: 154504.97 | D34: =C34* Inputs!$C$11 * Inputs!$C$15 -> 69527.234 | E34: 227962.71 | F34: =E34-$E$32 -> 5867.4773 | G34: =F34/$E$32 *100 -> 2.6418745
A40: Mortality Rate Sensitivity Analysis
A42: Mortality Change | B42: Total Liability | C42: Change from Base | D42: % Change
A43: (-)10% | B43: 225790.9 | C43: =B43-$B$44 -> 3695.6709 | D43: =C43/$B$44 *100 -> 1.6640028
A44: 0 | B44: 222095.23 | C44: =B44-$B$44 -> 0 | D44: =C44/$B$44 *100 -> 0
A45: (+)10% | B45: 218505.83 | C45: =B45-$B$44 -> -3589.3983 | D45: =C45/$B$44 *100 -> -1.6161528
A51: Accrual Rate Sensitivity Analysis
A53: Accrual Rate Adjustment | B53: Annual Pension | C53: Total Liability | D53: Change from Base | E53: % Change
A54: 1.35% (-10%) | B54: 58982.478 | C54: 199885.71 | D54: =C54-$C$55 -> -22209.523 | E54: =D54/$C$55 *100 -> -10
A55: 0.015 | B55: 65536.087 | C55: 222095.23 | D55: =C55-$C$55 -> 0 | E55: =D55/$C$55 *100 -> 0
A56: 1.65% (+10%) | B56: 72089.695 | C56: 244304.75 | D56: =C56-$C$55 -> 22209.523 | E56: =D56/$C$55 *100 -> 10
A62: Tornado Chart Data
A64: Assumption | B64: Low Value | C64: Base Value | D64: High Value | E64: Impact on Liability
A65: Discount Rate | B65: =B8 -> 108322.66 | C65: =B6 -> 222095.23 | D65: =B4 -> 467444.42 | E65: =D65-B65 -> 359121.76
A66: Salary Growth | B66: =D17 -> 105340.16 | C66: =D19 -> 222095.23 | D66: =D21 -> 467444.42 | E66: =D66-B66 -> 362104.26
A67: Accrual Rate | B67: =C54 -> 199885.71 | C67: =C55 -> 222095.23 | D67: =C56 -> 244304.75 | E67: =D67-B67 -> 44419.046
A68: Retirement Age | B68: =E30 -> 215417.09 | C68: =E32 -> 222095.23 | D68: =E34 -> 227962.71 | E68: =D68-B68 -> 12545.616
A69: Mortality Rate | B69: =B45 -> 218505.83 | C69: =B44 -> 222095.23 | D69: =B43 -> 225790.9 | E69: =D69-B69 -> 7285.0691
A72: Assumption | B72: Change Low | C72: Change High
A73: Discount Rate | B73: =B65-C65 -> -113772.57 | C73: =D65-C65 -> 245349.19
...

Sheet Charts
B1: Pension Liability Analysis – Visualizations
B5: Employee Profile Age: 35 Retirement: 65 Salary: $60,000

Sheet Documentation
A1: PENSION LIABILITY VALUATION MODEL — DOCUMENTATION
A5: PURPOSE: This model calculates the present value of future pension obligations for a defined benefit pension plan.
A7: Methodology:
A8: 1. Calculate final salary using compound salary growth Final Salary = Starting Salary * (1 + Salary Growth Rate) ^ Years to Retirement
A10: 2. Annual Pension Benefit Benefit = Accrual Rate × Years of Service × Final Salary
A12: 3. Pension Payment Projection Project annual pension from retirement age until assumed maximum age (life expectancy).
A14: 4. Survival Adjustment Expected Payment = Pension × Survival Probability Survival Probability = Previous Survival Probability × (1 – Mortality Rate)
A17: 5. Discount to Present Value PV = Expected Payment ÷ (1 + Discount Rate) ^ Years from Now
A19: 6. Total Liability Pension Liability = SUM of all discounted expected payments
A23: Key Assumptions:
A24: 1. Mortality: Simplified mortality starting at 1% at age 65 and increasing 10% each year. (Real-world models use SOA tables such as RP-2014 or Pri-2012.)
A26: 2. Discount Rate: 5%, representing long-term expected return on pension assets.
... A46: 4. Pension buyouts and settlements
